Workbook

Sheet Forecast
A1: S&OP 移動預測表
A2: 每個產品 7 行：目標、當月實際出貨、實銷、N-1預估、當月出貨預測、目標達成率、預估準確率。業務每月填實銷與當月出貨預測，N-1預估由 Forecast_History 自動帶入。
A4: 本期月份 | B4: =Settings!$B$2 | C4: 箱數
A5: 國際條碼 | B5: 產品名稱(EN) | C5: 產品名稱(CN) | D5: 項目 | E5: 46023 | F5: 46054 | G5: 46082 | H5: 46113 | I5: 46143 | J5: 46174 | K5: 46204 | L5: 46235 | M5: 46266 | N5: 46296 | O5: 46327 | P5: 46357 | Q5: 2026合計 | R5: 46388 | S5: 46419 | T5: 46447 | U5: 46478 | V5: 46508 | W5: 46539 | X5: 46569 | Y5: 46600 | Z5: 46631 | AA5: 46661 | AB5: 46692 | AC5: 46722 | AD5: 2027合計 | AE5: 備註
A6: 8697343116899 | B6: FEAST IQF CHURROS CUT POTATO 10x1 kg | C6: FEAST 香脆切薯條 | D6: 目標 | H6: 48.5 | I6: 51.610169 | J6: 51.610169 | K6: 51.610169 | L6: 56.771186 | M6: 49.029661 | N6: 56.771186 | O6: 49.029661 | P6: 56.771186 | Q6: =IF(COUNTA(E6:P6)=0,"",SUM(E6:P6)) | R6: 51.610169 | S6: 51.610169 | T6: 51.610169 | AD6: =IF(COUNTA(R6:AC6)=0,"",SUM(R6:AC6))
D7: 當月實際出貨 | H7: 9.7 | I7: 10.322034 | Q7: =IF(COUNTA(E7:P7)=0,"",SUM(E7:P7)) | AD7: =IF(COUNTA(R7:AC7)=0,"",SUM(R7:AC7))
D8: 實銷 | F8: 8.4 | G8: 11.9 | H8: 9.7 | Q8: =IF(COUNTA(E8:P8)=0,"",SUM(E8:P8)) | AD8: =IF(COUNTA(R8:AC8)=0,"",SUM(R8:AC8))
D9: N-1預估 | E9: =IF($A6="","",SUMIFS(Forecast_History!$F:$F,Forecast_History!$A:$A,EDATE(E$5,-1),Forecast_History!$B:$B,$A6,Forecast_History!$E:$E,E$5)) | F9: =IF($A6="","",SUMIFS(Forecast_History!$F:$F,Forecast_History!$A:$A,EDATE(F$5,-1),Forecast_History!$B:$B,$A6,Forecast_History!$E:$E,F$5)) | G9: =IF($A6="","",SUMIFS(Forecast_History!$F:$F,Forecast_History!$A:$A,EDATE(G$5,-1),Forecast_History!$B:$B,$A6,Forecast_History!$E:$E,G$5)) | H9: =IF($A6="","",SUMIFS(Forecast_History!$F:$F,Forecast_History!$A:$A,EDATE(H$5,-1),Forecast_History!$B:$B,$A6,Forecast_History!$E:$E,H$5)) | I9: =IF($A6="","",SUMIFS(Forecast_History!$F:$F,Forecast_History!$A:$A,EDATE(I$5,-1),Forecast_History!$B:$B,$A6,Forecast_History!$E:$E,I$5)) | J9: =IF($A6="","",SUMIFS(Forecast_History!$F:$F,Forecast_History!$A:$A,EDATE(J$5,-1),Forecast_History!$B:$B,$A6,Forecast_History!$E:$E,J$5)) | K9: =IF($A6="","",SUMIFS(Forecast_History!$F:$F,Forecast_History!$A:$A,EDATE(K$5,-1),Forecast_History!$B:$B,$A6,Forecast_History!$E:$E,K$5)) | L9: =IF($A6="","",SUMIFS(Forecast_History!$F:$F,Forecast_History!$A:$A,EDATE(L$5,-1),Forecast_History!$B:$B,$A6,Forecast_History!$E:$E,L$5)) | ... P9: =IF($A6="","",SUMIFS(Forecast_History!$F:$F,Forecast_History!$A:$A,EDATE(P$5,-1),Forecast_History!$B:$B,$A6,Forecast_History!$E:$E,P$5)) | Q9: =IF(COUNTA(E9:P9)=0,"",SUM(E9:P9)) | R9: =IF($A6="","",SUMIFS(Forecast_History!$F:$F,Forecast_History!$A:$A,EDATE(R$5,-1),Forecast_History!$B:$B,$A6,Forecast_History!$E:$E,R$5)) | S9: =IF($A6="","",SUMIFS(Forecast_History!$F:$F,Forecast_History!$A:$A,EDATE(S$5,-1),Forecast_History!$B:$B,$A6,Forecast_History!$E:$E,S$5)) | T9: =IF($A6="","",SUMIFS(Forecast_History!$F:$F,Forecast_History!$A:$A,EDATE(T$5,-1),Forecast_History!$B:$B,$A6,Forecast_History!$E:$E,T$5)) | U9: =IF($A6="","",SUMIFS(Forecast_History!$F:$F,Forecast_History!$A:$A,EDATE(U$5,-1),Forecast_History!$B:$B,$A6,Forecast_History!$E:$E,U$5)) | V9: =IF($A6="","",SUMIFS(Forecast_History!$F:$F,Forecast_History!$A:$A,EDATE(V$5,-1),Forecast_History!$B:$B,$A6,Forecast_History!$E:$E,V$5)) | W9: =IF($A6="","",SUMIFS(Forecast_History!$F:$F,Forecast_History!$A:$A,EDATE(W$5,-1),Forecast_History!$B:$B,$A6,Forecast_History!$E:$E,W$5)) | X9: =IF($A6="","",SUMIFS(Forecast_History!$F:$F,Forecast_History!$A:$A,EDATE(X$5,-1),Forecast_History!$B:$B,$A6,Forecast_History!$E:$E,X$5)) | Y9: =IF($A6="","",SUMIFS(Forecast_History!$F:$F,Forecast_History!$A:$A,EDATE(Y$5,-1),Forecast_History!$B:$B,$A6,Forecast_History!$E:$E,Y$5)) | ... AC9: =IF($A6="","",SUMIFS(Forecast_History!$F:$F,Forecast_History!$A:$A,EDATE(AC$5,-1),Forecast_History!$B:$B,$A6,Forecast_History!$E:$E,AC$5)) | AD9: =IF(COUNTA(R9:AC9)=0,"",SUM(R9:AC9))
D10: 當月出貨預測 | Q10: =IF(COUNTA(E10:P10)=0,"",SUM(E10:P10)) | AD10: =IF(COUNTA(R10:AC10)=0,"",SUM(R10:AC10))
D11: 目標達成率 | E11: =IFERROR(E7/E6,"") | F11: =IFERROR(F7/F6,"") | G11: =IFERROR(G7/G6,"") | H11: =IFERROR(H7/H6,"") | I11: =IFERROR(I7/I6,"") | J11: =IFERROR(J7/J6,"") | K11: =IFERROR(K7/K6,"") | L11: =IFERROR(L7/L6,"") | ... P11: =IFERROR(P7/P6,"") | R11: =IFERROR(R7/R6,"") | S11: =IFERROR(S7/S6,"") | T11: =IFERROR(T7/T6,"") | U11: =IFERROR(U7/U6,"") | V11: =IFERROR(V7/V6,"") | W11: =IFERROR(W7/W6,"") | X11: =IFERROR(X7/X6,"") | Y11: =IFERROR(Y7/Y6,"") | ... AC11: =IFERROR(AC7/AC6,"")
D12: 預估準確率 | E12: =IFERROR(E7/E10,"") | F12: =IFERROR(F7/F10,"") | G12: =IFERROR(G7/G10,"") | H12: =IFERROR(H7/H10,"") | I12: =IFERROR(I7/I10,"") | J12: =IFERROR(J7/J10,"") | K12: =IFERROR(K7/K10,"") | L12: =IFERROR(L7/L10,"") | ... P12: =IFERROR(P7/P10,"") | R12: =IFERROR(R7/R10,"") | S12: =IFERROR(S7/S10,"") | T12: =IFERROR(T7/T10,"") | U12: =IFERROR(U7/U10,"") | V12: =IFERROR(V7/V10,"") | W12: =IFERROR(W7/W10,"") | X12: =IFERROR(X7/X10,"") | Y12: =IFERROR(Y7/Y10,"") | ... AC12: =IFERROR(AC7/AC10,"")
A13: 8697343600022 | B13: FEAST IQF WEDGE POTATO 10x1 kg | C13: FEAST 楔型薯塊 | D13: 目標 | H13: 108 | I13: 108.81356 | J13: 108.81356 | K13: 119.69492 | L13: 103.37288 | M13: 119.69492 | N13: 103.37288 | O13: 119.69492 | P13: 108.81356 | Q13: =IF(COUNTA(E13:P13)=0,"",SUM(E13:P13)) | R13: 108.81356 | S13: 108.81356 | T13: 108.81356 | AD13: =IF(COUNTA(R13:AC13)=0,"",SUM(R13:AC13))
D14: 當月實際出貨 | H14: 21.6 | I14: 21.762712 | Q14: =IF(COUNTA(E14:P14)=0,"",SUM(E14:P14)) | AD14: =IF(COUNTA(R14:AC14)=0,"",SUM(R14:AC14))
D15: 實銷 | F15: 21.4 | G15: 21.4 | H15: 21.6 | Q15: =IF(COUNTA(E15:P15)=0,"",SUM(E15:P15)) | AD15: =IF(COUNTA(R15:AC15)=0,"",SUM(R15:AC15))
D16: N-1預估 | E16: =IF($A13="","",SUMIFS(Forecast_History!$F:$F,Forecast_History!$A:$A,EDATE(E$5,-1),Forecast_History!$B:$B,$A13,Forecast_History!$E:$E,E$5)) | F16: =IF($A13="","",SUMIFS(Forecast_History!$F:$F,Forecast_History!$A:$A,EDATE(F$5,-1),Forecast_History!$B:$B,$A13,Forecast_History!$E:$E,F$5)) | G16: =IF($A13="","",SUMIFS(Forecast_History!$F:$F,Forecast_History!$A:$A,EDATE(G$5,-1),Forecast_History!$B:$B,$A13,Forecast_History!$E:$E,G$5)) | H16: =IF($A13="","",SUMIFS(Forecast_History!$F:$F,Forecast_History!$A:$A,EDATE(H$5,-1),Forecast_History!$B:$B,$A13,Forecast_History!$E:$E,H$5)) | I16: =IF($A13="","",SUMIFS(Forecast_History!$F:$F,Forecast_History!$A:$A,EDATE(I$5,-1),Forecast_History!$B:$B,$A13,Forecast_History!$E:$E,I$5)) | J16: =IF($A13="","",SUMIFS(Forecast_History!$F:$F,Forecast_History!$A:$A,EDATE(J$5,-1),Forecast_History!$B:$B,$A13,Forecast_History!$E:$E,J$5)) | K16: =IF($A13="","",SUMIFS(Forecast_History!$F:$F,Forecast_History!$A:$A,EDATE(K$5,-1),Forecast_History!$B:$B,$A13,Forecast_History!$E:$E,K$5)) | L16: =IF($A13="","",SUMIFS(Forecast_History!$F:$F,Forecast_History!$A:$A,EDATE(L$5,-1),Forecast_History!$B:$B,$A13,Forecast_History!$E:$E,L$5)) | ... P16: =IF($A13="","",SUMIFS(Forecast_History!$F:$F,Forecast_History!$A:$A,EDATE(P$5,-1),Forecast_History!$B:$B,$A13,Forecast_History!$E:$E,P$5)) | Q16: =IF(COUNTA(E16:P16)=0,"",SUM(E16:P16)) | R16: =IF($A13="","",SUMIFS(Forecast_History!$F:$F,Forecast_History!$A:$A,EDATE(R$5,-1),Forecast_History!$B:$B,$A13,Forecast_History!$E:$E,R$5)) | S16: =IF($A13="","",SUMIFS(Forecast_History!$F:$F,Forecast_History!$A:$A,EDATE(S$5,-1),Forecast_History!$B:$B,$A13,Forecast_History!$E:$E,S$5)) | T16: =IF($A13="","",SUMIFS(Forecast_History!$F:$F,Forecast_History!$A:$A,EDATE(T$5,-1),Forecast_History!$B:$B,$A13,Forecast_History!$E:$E,T$5)) | U16: =IF($A13="","",SUMIFS(Forecast_History!$F:$F,Forecast_History!$A:$A,EDATE(U$5,-1),Forecast_History!$B:$B,$A13,Forecast_History!$E:$E,U$5)) | V16: =IF($A13="","",SUMIFS(Forecast_History!$F:$F,Forecast_History!$A:$A,EDATE(V$5,-1),Forecast_History!$B:$B,$A13,Forecast_History!$E:$E,V$5)) | W16: =IF($A13="","",SUMIFS(Forecast_History!$F:$F,Forecast_History!$A:$A,EDATE(W$5,-1),Forecast_History!$B:$B,$A13,Forecast_History!$E:$E,W$5)) | X16: =IF($A13="","",SUMIFS(Forecast_History!$F:$F,Forecast_History!$A:$A,EDATE(X$5,-1),Forecast_History!$B:$B,$A13,Forecast_History!$E:$E,X$5)) | Y16: =IF($A13="","",SUMIFS(Forecast_History!$F:$F,Forecast_History!$A:$A,EDATE(Y$5,-1),Forecast_History!$B:$B,$A13,Forecast_History!$E:$E,Y$5)) | ... AC16: =IF($A13="","",SUMIFS(Forecast_History!$F:$F,Forecast_History!$A:$A,EDATE(AC$5,-1),Forecast_History!$B:$B,$A13,Forecast_History!$E:$E,AC$5)) | AD16: =IF(COUNTA(R16:AC16)=0,"",SUM(R16:AC16))
D17: 當月出貨預測 | Q17: =IF(COUNTA(E17:P17)=0,"",SUM(E17:P17)) | AD17: =IF(COUNTA(R17:AC17)=0,"",SUM(R17:AC17))
D18: 目標達成率 | E18: =IFERROR(E14/E13,"") | F18: =IFERROR(F14/F13,"") | G18: =IFERROR(G14/G13,"") | H18: =IFERROR(H14/H13,"") | I18: =IFERROR(I14/I13,"") | J18: =IFERROR(J14/J13,"") | K18: =IFERROR(K14/K13,"") | L18: =IFERROR(L14/L13,"") | ... P18: =IFERROR(P14/P13,"") | R18: =IFERROR(R14/R13,"") | S18: =IFERROR(S14/S13,"") | T18: =IFERROR(T14/T13,"") | U18: =IFERROR(U14/U13,"") | V18: =IFERROR(V14/V13,"") | W18: =IFERROR(W14/W13,"") | X18: =IFERROR(X14/X13,"") | Y18: =IFERROR(Y14/Y13,"") | ... AC18: =IFERROR(AC14/AC13,"")
D19: 預估準確率 | E19: =IFERROR(E14/E17,"") | F19: =IFERROR(F14/F17,"") | G19: =IFERROR(G14/G17,"") | H19: =IFERROR(H14/H17,"") | I19: =IFERROR(I14/I17,"") | J19: =IFERROR(J14/J17,"") | K19: =IFERROR(K14/K17,"") | L19: =IFERROR(L14/L17,"") | ... P19: =IFERROR(P14/P17,"") | R19: =IFERROR(R14/R17,"") | S19: =IFERROR(S14/S17,"") | T19: =IFERROR(T14/T17,"") | U19: =IFERROR(U14/U17,"") | V19: =IFERROR(V14/V17,"") | W19: =IFERROR(W14/W17,"") | X19: =IFERROR(X14/X17,"") | Y19: =IFERROR(Y14/Y17,"") | ... AC19: =IFERROR(AC14/AC17,"")
A20: 8697343464225 | B20: FEAST IQF FRENCH FRIES 10*10 mm 10x1 kg | C20: FEAST 10*10mm 薯條 | D20: 目標 | H20: 45 | I20: 92.542373 | J20: 92.542373 | K20: 120.30508 | L20: 83.288136 | M20: 120.30508 | N20: 83.288136 | O20: 120.30508 | P20: 92.542373 | Q20: =IF(COUNTA(E20:P20)=0,"",SUM(E20:P20)) | R20: 92.542373 | S20: 92.542373 | T20: 92.542373 | AD20: =IF(COUNTA(R20:AC20)=0,"",SUM(R20:AC20))
D21: 當月實際出貨 | H21: 9 | I21: 18.508475 | Q21: =IF(COUNTA(E21:P21)=0,"",SUM(E21:P21)) | AD21: =IF(COUNTA(R21:AC21)=0,"",SUM(R21:AC21))
D22: 實銷 | F22: 20.9 | G22: 15.5 | H22: 9 | Q22: =IF(COUNTA(E22:P22)=0,"",SUM(E22:P22)) | AD22: =IF(COUNTA(R22:AC22)=0,"",SUM(R22:AC22))
D23: N-1預估 | E23: =IF($A20="","",SUMIFS(Forecast_History!$F:$F,Forecast_History!$A:$A,EDATE(E$5,-1),Forecast_History!$B:$B,$A20,Forecast_History!$E:$E,E$5)) | F23: =IF($A20="","",SUMIFS(Forecast_History!$F:$F,Forecast_History!$A:$A,EDATE(F$5,-1),Forecast_History!$B:$B,$A20,Forecast_History!$E:$E,F$5)) | G23: =IF($A20="","",SUMIFS(Forecast_History!$F:$F,Forecast_History!$A:$A,EDATE(G$5,-1),Forecast_History!$B:$B,$A20,Forecast_History!$E:$E,G$5)) | H23: =IF($A20="","",SUMIFS(Forecast_History!$F:$F,Forecast_History!$A:$A,EDATE(H$5,-1),Forecast_History!$B:$B,$A20,Forecast_History!$E:$E,H$5)) | I23: =IF($A20="","",SUMIFS(Forecast_History!$F:$F,Forecast_History!$A:$A,EDATE(I$5,-1),Forecast_History!$B:$B,$A20,Forecast_History!$E:$E,I$5)) | J23: =IF($A20="","",SUMIFS(Forecast_History!$F:$F,Forecast_History!$A:$A,EDATE(J$5,-1),Forecast_History!$B:$B,$A20,Forecast_History!$E:$E,J$5)) | K23: =IF($A20="","",SUMIFS(Forecast_History!$F:$F,Forecast_History!$A:$A,EDATE(K$5,-1),Forecast_History!$B:$B,$A20,Forecast_History!$E:$E,K$5)) | L23: =IF($A20="","",SUMIFS(Forecast_History!$F:$F,Forecast_History!$A:$A,EDATE(L$5,-1),Forecast_History!$B:$B,$A20,Forecast_History!$E:$E,L$5)) | ... P23: =IF($A20="","",SUMIFS(Forecast_History!$F:$F,Forecast_History!$A:$A,EDATE(P$5,-1),Forecast_History!$B:$B,$A20,Forecast_History!$E:$E,P$5)) | Q23: =IF(COUNTA(E23:P23)=0,"",SUM(E23:P23)) | R23: =IF($A20="","",SUMIFS(Forecast_History!$F:$F,Forecast_History!$A:$A,EDATE(R$5,-1),Forecast_History!$B:$B,$A20,Forecast_History!$E:$E,R$5)) | S23: =IF($A20="","",SUMIFS(Forecast_History!$F:$F,Forecast_History!$A:$A,EDATE(S$5,-1),Forecast_History!$B:$B,$A20,Forecast_History!$E:$E,S$5)) | T23: =IF($A20="","",SUMIFS(Forecast_History!$F:$F,Forecast_History!$A:$A,EDATE(T$5,-1),Forecast_History!$B:$B,$A20,Forecast_History!$E:$E,T$5)) | U23: =IF($A20="","",SUMIFS(Forecast_History!$F:$F,Forecast_History!$A:$A,EDATE(U$5,-1),Forecast_History!$B:$B,$A20,Forecast_History!$E:$E,U$5)) | V23: =IF($A20="","",SUMIFS(Forecast_History!$F:$F,Forecast_History!$A:$A,EDATE(V$5,-1),Forecast_History!$B:$B,$A20,Forecast_History!$E:$E,V$5)) | W23: =IF($A20="","",SUMIFS(Forecast_History!$F:$F,Forecast_History!$A:$A,EDATE(W$5,-1),Forecast_History!$B:$B,$A20,Forecast_History!$E:$E,W$5)) | X23: =IF($A20="","",SUMIFS(Forecast_History!$F:$F,Forecast_History!$A:$A,EDATE(X$5,-1),Forecast_History!$B:$B,$A20,Forecast_History!$E:$E,X$5)) | Y23: =IF($A20="","",SUMIFS(Forecast_History!$F:$F,Forecast_History!$A:$A,EDATE(Y$5,-1),Forecast_History!$B:$B,$A20,Forecast_History!$E:$E,Y$5)) | ... AC23: =IF($A20="","",SUMIFS(Forecast_History!$F:$F,Forecast_History!$A:$A,EDATE(AC$5,-1),Forecast_History!$B:$B,$A20,Forecast_History!$E:$E,AC$5)) | AD23: =IF(COUNTA(R23:AC23)=0,"",SUM(R23:AC23))
D24: 當月出貨預測 | Q24: =IF(COUNTA(E24:P24)=0,"",SUM(E24:P24)) | AD24: =IF(COUNTA(R24:AC24)=0,"",SUM(R24:AC24))
D25: 目標達成率 | E25: =IFERROR(E21/E20,"") | F25: =IFERROR(F21/F20,"") | G25: =IFERROR(G21/G20,"") | H25: =IFERROR(H21/H20,"") | I25: =IFERROR(I21/I20,"") | J25: =IFERROR(J21/J20,"") | K25: =IFERROR(K21/K20,"") | L25: =IFERROR(L21/L20,"") | ... P25: =IFERROR(P21/P20,"") | R25: =IFERROR(R21/R20,"") | S25: =IFERROR(S21/S20,"") | T25: =IFERROR(T21/T20,"") | U25: =IFERROR(U21/U20,"") | V25: =IFERROR(V21/V20,"") | W25: =IFERROR(W21/W20,"") | X25: =IFERROR(X21/X20,"") | Y25: =IFERROR(Y21/Y20,"") | ... AC25: =IFERROR(AC21/AC20,"")
D26: 預估準確率 | E26: =IFERROR(E21/E24,"") | F26: =IFERROR(F21/F24,"") | G26: =IFERROR(G21/G24,"") | H26: =IFERROR(H21/H24,"") | I26: =IFERROR(I21/I24,"") | J26: =IFERROR(J21/J24,"") | K26: =IFERROR(K21/K24,"") | L26: =IFERROR(L21/L24,"") | ... P26: =IFERROR(P21/P24,"") | R26: =IFERROR(R21/R24,"") | S26: =IFERROR(S21/S24,"") | T26: =IFERROR(T21/T24,"") | U26: =IFERROR(U21/U24,"") | V26: =IFERROR(V21/V24,"") | W26: =IFERROR(W21/W24,"") | X26: =IFERROR(X21/X24,"") | Y26: =IFERROR(Y21/Y24,"") | ... AC26: =IFERROR(AC21/AC24,"")
A27: 8697343600039 | B27: FEAST IQF FRENCH FRIES 7*7 mm 10x1 kg | C27: FEAST 7*7mm 薯條 | D27: 目標 | H27: 63.5 | I27: 148.98305 | J27: 148.98305 | K27: 178.77966 | L27: 134.08475 | M27: 178.77966 | N27: 134.08475 | O27: 178.77966 | P27: 148.98305 | Q27: =IF(COUNTA(E27:P27)=0,"",SUM(E27:P27)) | R27: 148.98305 | S27: 148.98305 | T27: 148.98305 | AD27: =IF(COUNTA(R27:AC27)=0,"",SUM(R27:AC27))
D28: 當月實際出貨 | H28: 12.7 | I28: 29.79661 | Q28: =IF(COUNTA(E28:P28)=0,"",SUM(E28:P28)) | AD28: =IF(COUNTA(R28:AC28)=0,"",SUM(R28:AC28))
D29: 實銷 | F29: 32.4 | G29: 26.2 | H29: 12.7 | Q29: =IF(COUNTA(E29:P29)=0,"",SUM(E29:P29)) | AD29: =IF(COUNTA(R29:AC29)=0,"",SUM(R29:AC29))
D30: N-1預估 | E30: =IF($A27="","",SUMIFS(Forecast_History!$F:$F,Forecast_History!$A:$A,EDATE(E$5,-1),Forecast_History!$B:$B,$A27,Forecast_History!$E:$E,E$5)) | F30: =IF($A27="","",SUMIFS(Forecast_History!$F:$F,Forecast_History!$A:$A,EDATE(F$5,-1),Forecast_History!$B:$B,$A27,Forecast_History!$E:$E,F$5)) | G30: =IF($A27="","",SUMIFS(Forecast_History!$F:$F,Forecast_History!$A:$A,EDATE(G$5,-1),Forecast_History!$B:$B,$A27,Forecast_History!$E:$E,G$5)) | H30: =IF($A27="","",SUMIFS(Forecast_History!$F:$F,Forecast_History!$A:$A,EDATE(H$5,-1),Forecast_History!$B:$B,$A27,Forecast_History!$E:$E,H$5)) | I30: =IF($A27="","",SUMIFS(Forecast_History!$F:$F,Forecast_History!$A:$A,EDATE(I$5,-1),Forecast_History!$B:$B,$A27,Forecast_History!$E:$E,I$5)) | J30: =IF($A27="","",SUMIFS(Forecast_History!$F:$F,Forecast_History!$A:$A,EDATE(J$5,-1),Forecast_History!$B:$B,$A27,Forecast_History!$E:$E,J$5)) | K30: =IF($A27="","",SUMIFS(Forecast_History!$F:$F,Forecast_History!$A:$A,EDATE(K$5,-1),Forecast_History!$B:$B,$A27,Forecast_History!$E:$E,K$5)) | L30: =IF($A27="","",SUMIFS(Forecast_History!$F:$F,Forecast_History!$A:$A,EDATE(L$5,-1),Forecast_History!$B:$B,$A27,Forecast_History!$E:$E,L$5)) | ... P30: =IF($A27="","",SUMIFS(Forecast_History!$F:$F,Forecast_History!$A:$A,EDATE(P$5,-1),Forecast_History!$B:$B,$A27,Forecast_History!$E:$E,P$5)) | Q30: =IF(COUNTA(E30:P30)=0,"",SUM(E30:P30)) | R30: =IF($A27="","",SUMIFS(Forecast_History!$F:$F,Forecast_History!$A:$A,EDATE(R$5,-1),Forecast_History!$B:$B,$A27,Forecast_History!$E:$E,R$5)) | S30: =IF($A27="","",SUMIFS(Forecast_History!$F:$F,Forecast_History!$A:$A,EDATE(S$5,-1),Forecast_History!$B:$B,$A27,Forecast_History!$E:$E,S$5)) | T30: =IF($A27="","",SUMIFS(Forecast_History!$F:$F,Forecast_History!$A:$A,EDATE(T$5,-1),Forecast_History!$B:$B,$A27,Forecast_History!$E:$E,T$5)) | U30: =IF($A27="","",SUMIFS(Forecast_History!$F:$F,Forecast_History!$A:$A,EDATE(U$5,-1),Forecast_History!$B:$B,$A27,Forecast_History!$E:$E,U$5)) | V30: =IF($A27="","",SUMIFS(Forecast_History!$F:$F,Forecast_History!$A:$A,EDATE(V$5,-1),Forecast_History!$B:$B,$A27,Forecast_History!$E:$E,V$5)) | W30: =IF($A27="","",SUMIFS(Forecast_History!$F:$F,Forecast_History!$A:$A,EDATE(W$5,-1),Forecast_History!$B:$B,$A27,Forecast_History!$E:$E,W$5)) | X30: =IF($A27="","",SUMIFS(Forecast_History!$F:$F,Forecast_History!$A:$A,EDATE(X$5,-1),Forecast_History!$B:$B,$A27,Forecast_History!$E:$E,X$5)) | Y30: =IF($A27="","",SUMIFS(Forecast_History!$F:$F,Forecast_History!$A:$A,EDATE(Y$5,-1),Forecast_History!$B:$B,$A27,Forecast_History!$E:$E,Y$5)) | ... AC30: =IF($A27="","",SUMIFS(Forecast_History!$F:$F,Forecast_History!$A:$A,EDATE(AC$5,-1),Forecast_History!$B:$B,$A27,Forecast_History!$E:$E,AC$5)) | AD30: =IF(COUNTA(R30:AC30)=0,"",SUM(R30:AC30))
D31: 當月出貨預測 | Q31: =IF(COUNTA(E31:P31)=0,"",SUM(E31:P31)) | AD31: =IF(COUNTA(R31:AC31)=0,"",SUM(R31:AC31))
D32: 目標達成率 | E32: =IFERROR(E28/E27,"") | F32: =IFERROR(F28/F27,"") | G32: =IFERROR(G28/G27,"") | H32: =IFERROR(H28/H27,"") | I32: =IFERROR(I28/I27,"") | J32: =IFERROR(J28/J27,"") | K32: =IFERROR(K28/K27,"") | L32: =IFERROR(L28/L27,"") | ... P32: =IFERROR(P28/P27,"") | R32: =IFERROR(R28/R27,"") | S32: =IFERROR(S28/S27,"") | T32: =IFERROR(T28/T27,"") | U32: =IFERROR(U28/U27,"") | V32: =IFERROR(V28/V27,"") | W32: =IFERROR(W28/W27,"") | X32: =IFERROR(X28/X27,"") | Y32: =IFERROR(Y28/Y27,"") | ... AC32: =IFERROR(AC28/AC27,"")
D33: 預估準確率 | E33: =IFERROR(E28/E31,"") | F33: =IFERROR(F28/F31,"") | G33: =IFERROR(G28/G31,"") | H33: =IFERROR(H28/H31,"") | I33: =IFERROR(I28/I31,"") | J33: =IFERROR(J28/J31,"") | K33: =IFERROR(K28/K31,"") | L33: =IFERROR(L28/L31,"") | ... P33: =IFERROR(P28/P31,"") | R33: =IFERROR(R28/R31,"") | S33: =IFERROR(S28/S31,"") | T33: =IFERROR(T28/T31,"") | U33: =IFERROR(U28/U31,"") | V33: =IFERROR(V28/V31,"") | W33: =IFERROR(W28/W31,"") | X33: =IFERROR(X28/X31,"") | Y33: =IFERROR(Y28/Y31,"") | ... AC33: =IFERROR(AC28/AC31,"")
A34: 8697343650027 | B34: FEAST IQF ONION RINGS 12*450 GR | C34: 洋蔥圈 | D34: 目標 | H34: 152.9 | I34: 167.63889 | J34: 216.94444 | K34: 284.19722 | L34: 195.25 | M34: 284.19722 | N34: 195.25 | O34: 284.19722 | P34: 195.25 | Q34: =IF(COUNTA(E34:P34)=0,"",SUM(E34:P34)) | R34: 216.94444 | S34: 216.94444 | T34: 216.94444 | AD34: =IF(COUNTA(R34:AC34)=0,"",SUM(R34:AC34))
D35: 當月實際出貨 | H35: 30.58 | I35: 33.527778 | Q35: =IF(COUNTA(E35:P35)=0,"",SUM(E35:P35)) | AD35: =IF(COUNTA(R35:AC35)=0,"",SUM(R35:AC35))
D36: 實銷 | F36: 27.333333 | G36: 37.75 | H36: 30.583333 | Q36: =IF(COUNTA(E36:P36)=0,"",SUM(E36:P36)) | AD36: =IF(COUNTA(R36:AC36)=0,"",SUM(R36:AC36))
D37: N-1預估 | E37: =IF($A34="","",SUMIFS(Forecast_History!$F:$F,Forecast_History!$A:$A,EDATE(E$5,-1),Forecast_History!$B:$B,$A34,Forecast_History!$E:$E,E$5)) | F37: =IF($A34="","",SUMIFS(Forecast_History!$F:$F,Forecast_History!$A:$A,EDATE(F$5,-1),Forecast_History!$B:$B,$A34,Forecast_History!$E:$E,F$5)) | G37: =IF($A34="","",SUMIFS(Forecast_History!$F:$F,Forecast_History!$A:$A,EDATE(G$5,-1),Forecast_History!$B:$B,$A34,Forecast_History!$E:$E,G$5)) | H37: =IF($A34="","",SUMIFS(Forecast_History!$F:$F,Forecast_History!$A:$A,EDATE(H$5,-1),Forecast_History!$B:$B,$A34,Forecast_History!$E:$E,H$5)) | I37: =IF($A34="","",SUMIFS(Forecast_History!$F:$F,Forecast_History!$A:$A,EDATE(I$5,-1),Forecast_History!$B:$B,$A34,Forecast_History!$E:$E,I$5)) | J37: =IF($A34="","",SUMIFS(Forecast_History!$F:$F,Forecast_History!$A:$A,EDATE(J$5,-1),Forecast_History!$B:$B,$A34,Forecast_History!$E:$E,J$5)) | K37: =IF($A34="","",SUMIFS(Forecast_History!$F:$F,Forecast_History!$A:$A,EDATE(K$5,-1),Forecast_History!$B:$B,$A34,Forecast_History!$E:$E,K$5)) | L37: =IF($A34="","",SUMIFS(Forecast_History!$F:$F,Forecast_History!$A:$A,EDATE(L$5,-1),Forecast_History!$B:$B,$A34,Forecast_History!$E:$E,L$5)) | ... P37: =IF($A34="","",SUMIFS(Forecast_History!$F:$F,Forecast_History!$A:$A,EDATE(P$5,-1),Forecast_History!$B:$B,$A34,Forecast_History!$E:$E,P$5)) | Q37: =IF(COUNTA(E37:P37)=0,"",SUM(E37:P37)) | R37: =IF($A34="","",SUMIFS(Forecast_History!$F:$F,Forecast_History!$A:$A,EDATE(R$5,-1),Forecast_History!$B:$B,$A34,Forecast_History!$E:$E,R$5)) | S37: =IF($A34="","",SUMIFS(Forecast_History!$F:$F,Forecast_History!$A:$A,EDATE(S$5,-1),Forecast_History!$B:$B,$A34,Forecast_History!$E:$E,S$5)) | T37: =IF($A34="","",SUMIFS(Forecast_History!$F:$F,Forecast_History!$A:$A,EDATE(T$5,-1),Forecast_History!$B:$B,$A34,Forecast_History!$E:$E,T$5)) | U37: =IF($A34="","",SUMIFS(Forecast_History!$F:$F,Forecast_History!$A:$A,EDATE(U$5,-1),Forecast_History!$B:$B,$A34,Forecast_History!$E:$E,U$5)) | V37: =IF($A34="","",SUMIFS(Forecast_History!$F:$F,Forecast_History!$A:$A,EDATE(V$5,-1),Forecast_History!$B:$B,$A34,Forecast_History!$E:$E,V$5)) | W37: =IF($A34="","",SUMIFS(Forecast_History!$F:$F,Forecast_History!$A:$A,EDATE(W$5,-1),Forecast_History!$B:$B,$A34,Forecast_History!$E:$E,W$5)) | X37: =IF($A34="","",SUMIFS(Forecast_History!$F:$F,Forecast_History!$A:$A,EDATE(X$5,-1),Forecast_History!$B:$B,$A34,Forecast_History!$E:$E,X$5)) | Y37: =IF($A34="","",SUMIFS(Forecast_History!$F:$F,Forecast_History!$A:$A,EDATE(Y$5,-1),Forecast_History!$B:$B,$A34,Forecast_History!$E:$E,Y$5)) | ... AC37: =IF($A34="","",SUMIFS(Forecast_History!$F:$F,Forecast_History!$A:$A,EDATE(AC$5,-1),Forecast_History!$B:$B,$A34,Forecast_History!$E:$E,AC$5)) | AD37: =IF(COUNTA(R37:AC37)=0,"",SUM(R37:AC37))
D38: 當月出貨預測 | Q38: =IF(COUNTA(E38:P38)=0,"",SUM(E38:P38)) | AD38: =IF(COUNTA(R38:AC38)=0,"",SUM(R38:AC38))
D39: 目標達成率 | E39: =IFERROR(E35/E34,"") | F39: =IFERROR(F35/F34,"") | G39: =IFERROR(G35/G34,"") | H39: =IFERROR(H35/H34,"") | I39: =IFERROR(I35/I34,"") | J39: =IFERROR(J35/J34,"") | K39: =IFERROR(K35/K34,"") | L39: =IFERROR(L35/L34,"") | ... P39: =IFERROR(P35/P34,"") | R39: =IFERROR(R35/R34,"") | S39: =IFERROR(S35/S34,"") | T39: =IFERROR(T35/T34,"") | U39: =IFERROR(U35/U34,"") | V39: =IFERROR(V35/V34,"") | W39: =IFERROR(W35/W34,"") | X39: =IFERROR(X35/X34,"") | Y39: =IFERROR(Y35/Y34,"") | ... AC39: =IFERROR(AC35/AC34,"")
D40: 預估準確率 | E40: =IFERROR(E35/E38,"") | F40: =IFERROR(F35/F38,"") | G40: =IFERROR(G35/G38,"") | H40: =IFERROR(H35/H38,"") | I40: =IFERROR(I35/I38,"") | J40: =IFERROR(J35/J38,"") | K40: =IFERROR(K35/K38,"") | L40: =IFERROR(L35/L38,"") | ... P40: =IFERROR(P35/P38,"") | R40: =IFERROR(R35/R38,"") | S40: =IFERROR(S35/S38,"") | T40: =IFERROR(T35/T38,"") | U40: =IFERROR(U35/U38,"") | V40: =IFERROR(V35/V38,"") | W40: =IFERROR(W35/W38,"") | X40: =IFERROR(X35/X38,"") | Y40: =IFERROR(Y35/Y38,"") | ... AC40: =IFERROR(AC35/AC38,"")
A41: 8697343550129 | B41: FEAST IQF BROCCOLI 12*500 g | C41: 急凍青花菜 | D41: 目標 | H41: 79.583333 | I41: 69.736842 | J41: 69.736842 | K41: 80.197368 | L41: 80.197368 | M41: 80.197368 | N41: 80.197368 | O41: 80.197368 | P41: 80.197368 | Q41: =IF(COUNTA(E41:P41)=0,"",SUM(E41:P41)) | R41: 69.736842 | S41: 69.736842 | T41: 69.736842 | AD41: =IF(COUNTA(R41:AC41)=0,"",SUM(R41:AC41))
...

Sheet Forecast_History
A1: Forecast_History 每月預估快照
A2: 每月結束或開新月份前，把 Forecast 的「當月出貨預測」列轉成長表貼到這裡；下個月主表的 N-1預估會依版本月份、國際條碼、預估月份自動抓取。
A4: 版本月份 | B4: 國際條碼 | C4: 產品名稱(EN) | D4: 產品名稱(CN) | E4: 預估月份 | F4: 預估箱數 | G4: 備註

Sheet Settings
A1: 設定與填寫流程
A2: 本期月份 | B2: 46023
A4: 每月操作
A5: 1. 打開檔案後，在本頁 B2 設定本期月份，例如 2026-01。
A6: 2. 業務填 Forecast 工作表中各產品的「實銷」與「當月出貨預測」兩列，黃色底色為需填寫區。
A7: 3. 當月實際出貨填公司出貨數，實銷填客戶倉庫實際賣出數；達成率與準確率會自動計算。
A8: 4. 月結或開下個月前，將本月「當月出貨預測」整理貼到 Forecast_History，版本月份填本期月份。
A9: 5. 下個月把 B2 改成新月份後，Forecast 的 N-1預估會自動抓上個月版本的同產品、同預估月份數字。
A10: 6. Inventory_Planning 採用原進銷存格式，FCST 先放原進銷存每月預估出貨；訂貨以板為單位，Stock 依出貨需求與訂貨板數自動滾動。
A12: 目前產品清單
A13: 國際條碼 | B13: 產品名稱(EN) | C13: 產品名稱(CN)
A14: 8697343116899 | B14: FEAST IQF CHURROS CUT POTATO 10x1 kg | C14: FEAST 香脆切薯條
A15: 8697343600022 | B15: FEAST IQF WEDGE POTATO 10x1 kg | C15: FEAST 楔型薯塊
A16: 8697343464225 | B16: FEAST IQF FRENCH FRIES 10*10 mm 10x1 kg | C16: FEAST 10*10mm 薯條
A17: 8697343600039 | B17: FEAST IQF FRENCH FRIES 7*7 mm 10x1 kg | C17: FEAST 7*7mm 薯條
A18: 8697343650027 | B18: FEAST IQF ONION RINGS 12*450 GR | C18: 洋蔥圈
A19: 8697343550129 | B19: FEAST IQF BROCCOLI 12*500 g | C19: 急凍青花菜
A20: 8697343500200 | B20: FEAST IQF GREEN BEANS 16*450 GR | C20: 急凍四季豆
A21: 8697343550013 | B21: FEAST IQF GREEN PEAS | C21: 急速冷凍豌豆
B22: FEAST IQF SPINACH 12*450 GR | C22: 急速冷凍菠菜

Sheet Inventory_Planning
A1: 第二階段：進銷存與國際採購時程
A2: 採用原進銷存橫式格式：FCST/出貨需求先放原進銷存每月預估出貨，訂貨板數以板為單位。Stock = 前月底庫存 - 出貨需求 + 訂貨板數 × CTN/板。
A4: 本期月份 | B4: =Settings!$B$2 | C4: 需求與庫存單位：箱；訂貨單位：板
A5: 國際條碼 | B5: 產品名稱(EN) | C5: 產品名稱(CN) | D5: CTN/板 | E5: 項目 | F5: 2026-05月底庫存 | G5: 46174 | H5: 46204 | I5: 46235 | J5: 46266 | K5: 46296 | L5: 46327 | M5: 46357 | N5: 46388 | O5: 46419 | P5: 46447 | Q5: 46478 | R5: 46508 | S5: 46539 | T5: 46569 | U5: 46600 | V5: 46631 | W5: 46661 | X5: 46692 | Y5: 46722
A6: 8697343116899 | B6: FEAST IQF CHURROS CUT POTATO 10x1 kg | C6: FEAST 香脆切薯條 | D6: 56 | E6: FCST / 出貨需求 | G6: 10.322034 | H6: 10.322034 | I6: 11.354237 | J6: 9.8059322 | K6: 11.354237 | L6: 9.8059322 | M6: 11.354237 | N6: 10.322034 | O6: 10.322034 | P6: 10.322034 | Q6: 10.322034 | R6: 10.322034 | S6: 10.322034 | T6: 10.322034 | U6: 10.322034 | V6: 10.322034 | W6: 10.322034 | X6: 10.322034 | Y6: 10.322034
E7: order / 訂貨板數 | L7: 1
E8: Stock / 月末庫存 | F8: 127.67797 | G8: =IF(G6="","",$F8-G6+G7*$D6) -> 117.35593 | H8: =IF(H6="","",G8-H6+H7*$D6) -> 107.0339 | I8: =IF(I6="","",H8-I6+I7*$D6) -> 95.679661 | J8: =IF(J6="","",I8-J6+J7*$D6) -> 85.873729 | K8: =IF(K6="","",J8-K6+K7*$D6) -> 74.519492 | L8: =IF(L6="","",K8-L6+L7*$D6) -> 120.71356 | M8: =IF(M6="","",L8-M6+M7*$D6) -> 109.35932 | N8: =IF(N6="","",M8-N6+N7*$D6) -> 99.037288 | O8: =IF(O6="","",N8-O6+O7*$D6) -> 88.715254 | ... Y8: =IF(Y6="","",X8-Y6+Y7*$D6) -> -14.505085
E9: cover month / 可涵蓋月數 | F9: =IFERROR(F8/G6,"") -> 12.369458 | G9: =IFERROR(G8/G6,"") -> 11.369458 | H9: =IFERROR(H8/H6,"") -> 10.369458 | I9: =IFERROR(I8/I6,"") -> 8.4267801 | J9: =IFERROR(J8/J6,"") -> 8.7573243 | K9: =IFERROR(K8/K6,"") -> 6.5631438 | L9: =IFERROR(L8/L6,"") -> 12.310258 | M9: =IFERROR(M8/M6,"") -> 9.6315868 | N9: =IFERROR(N8/N6,"") -> 9.5947455 | ... Y9: =IFERROR(Y8/Y6,"") -> -1.4052545
A10: 8697343600022 | B10: FEAST IQF WEDGE POTATO 10x1 kg | C10: FEAST 楔型薯塊 | D10: 80 | E10: FCST / 出貨需求 | G10: 21.762712 | H10: 23.938983 | I10: 20.674576 | J10: 23.938983 | K10: 20.674576 | L10: 23.938983 | M10: 21.762712 | N10: 21.762712 | O10: 21.762712 | P10: 21.762712 | Q10: 21.762712 | R10: 21.762712 | S10: 21.762712 | T10: 21.762712 | U10: 21.762712 | V10: 21.762712 | W10: 21.762712 | X10: 21.762712 | Y10: 21.762712
E11: order / 訂貨板數 | G11: 1 | L11: 2
E12: Stock / 月末庫存 | F12: 69.837288 | G12: =IF(G10="","",$F12-G10+G11*$D10) -> 128.07458 | H12: =IF(H10="","",G12-H10+H11*$D10) -> 104.13559 | I12: =IF(I10="","",H12-I10+I11*$D10) -> 83.461017 | J12: =IF(J10="","",I12-J10+J11*$D10) -> 59.522034 | K12: =IF(K10="","",J12-K10+K11*$D10) -> 38.847458 | L12: =IF(L10="","",K12-L10+L11*$D10) -> 174.90847 | M12: =IF(M10="","",L12-M10+M11*$D10) -> 153.14576 | N12: =IF(N10="","",M12-N10+N11*$D10) -> 131.38305 | O12: =IF(O10="","",N12-O10+O11*$D10) -> 109.62034 | ... Y12: =IF(Y10="","",X12-Y10+Y11*$D10) -> -108.00678
E13: cover month / 可涵蓋月數 | F13: =IFERROR(F12/G10,"") -> 3.2090343 | G13: =IFERROR(G12/G10,"") -> 5.8850467 | H13: =IFERROR(H12/H10,"") -> 4.3500425 | I13: =IFERROR(I12/I10,"") -> 4.0368913 | J13: =IFERROR(J12/J10,"") -> 2.4864061 | K13: =IFERROR(K12/K10,"") -> 1.8789966 | L13: =IFERROR(L12/L10,"") -> 7.3064288 | M13: =IFERROR(M12/M10,"") -> 7.0370717 | N13: =IFERROR(N12/N10,"") -> 6.0370717 | ... Y13: =IFERROR(Y12/Y10,"") -> -4.9629283
A14: 8697343464225 | B14: FEAST IQF FRENCH FRIES 10*10 mm 10x1 kg | C14: FEAST 10*10mm 薯條 | D14: 64 | E14: FCST / 出貨需求 | G14: 18.508475 | H14: 24.061017 | I14: 16.657627 | J14: 24.061017 | K14: 16.657627 | L14: 24.061017 | M14: 18.508475 | N14: 18.508475 | O14: 18.508475 | P14: 18.508475 | Q14: 18.508475 | R14: 18.508475 | S14: 18.508475 | T14: 18.508475 | U14: 18.508475 | V14: 18.508475 | W14: 18.508475 | X14: 18.508475 | Y14: 18.508475
E15: order / 訂貨板數 | G15: 2 | L15: 1
E16: Stock / 月末庫存 | F16: 64.091525 | G16: =IF(G14="","",$F16-G14+G15*$D14) -> 173.58305 | H16: =IF(H14="","",G16-H14+H15*$D14) -> 149.52203 | I16: =IF(I14="","",H16-I14+I15*$D14) -> 132.86441 | J16: =IF(J14="","",I16-J14+J15*$D14) -> 108.80339 | K16: =IF(K14="","",J16-K14+K15*$D14) -> 92.145763 | L16: =IF(L14="","",K16-L14+L15*$D14) -> 132.08475 | M16: =IF(M14="","",L16-M14+M15*$D14) -> 113.57627 | N16: =IF(N14="","",M16-N14+N15*$D14) -> 95.067797 | O16: =IF(O14="","",N16-O14+O15*$D14) -> 76.559322 | ... Y16: =IF(Y14="","",X16-Y14+Y15*$D14) -> -108.52542
E17: cover month / 可涵蓋月數 | F17: =IFERROR(F16/G14,"") -> 3.4628205 | G17: =IFERROR(G16/G14,"") -> 9.3785714 | H17: =IFERROR(H16/H14,"") -> 6.2142857 | I17: =IFERROR(I16/I14,"") -> 7.9761905 | J17: =IFERROR(J16/J14,"") -> 4.521978 | K17: =IFERROR(K16/K14,"") -> 5.531746 | L17: =IFERROR(L16/L14,"") -> 5.4895745 | M17: =IFERROR(M16/M14,"") -> 6.1364469 | N17: =IFERROR(N16/N14,"") -> 5.1364469 | ... Y17: =IFERROR(Y16/Y14,"") -> -5.8635531
A18: 8697343600039 | B18: FEAST IQF FRENCH FRIES 7*7 mm 10x1 kg | C18: FEAST 7*7mm 薯條 | D18: 64 | E18: FCST / 出貨需求 | G18: 29.79661 | H18: 35.755932 | I18: 26.816949 | J18: 35.755932 | K18: 26.816949 | L18: 35.755932 | M18: 29.79661 | N18: 29.79661 | O18: 29.79661 | P18: 29.79661 | Q18: 29.79661 | R18: 29.79661 | S18: 29.79661 | T18: 29.79661 | U18: 29.79661 | V18: 29.79661 | W18: 29.79661 | X18: 29.79661 | Y18: 29.79661
E19: order / 訂貨板數 | G19: 5 | L19: 1
E20: Stock / 月末庫存 | F20: 26.90339 | G20: =IF(G18="","",$F20-G18+G19*$D18) -> 317.10678 | H20: =IF(H18="","",G20-H18+H19*$D18) -> 281.35085 | I20: =IF(I18="","",H20-I18+I19*$D18) -> 254.5339 | J20: =IF(J18="","",I20-J18+J19*$D18) -> 218.77797 | K20: =IF(K18="","",J20-K18+K19*$D18) -> 191.96102 | L20: =IF(L18="","",K20-L18+L19*$D18) -> 220.20508 | M20: =IF(M18="","",L20-M18+M19*$D18) -> 190.40847 | N20: =IF(N18="","",M20-N18+N19*$D18) -> 160.61186 | O20: =IF(O18="","",N20-O18+O19*$D18) -> 130.81525 | ... Y20: =IF(Y18="","",X20-Y18+Y19*$D18) -> -167.15085
E21: cover month / 可涵蓋月數 | F21: =IFERROR(F20/G18,"") -> 0.90290102 | G21: =IFERROR(G20/G18,"") -> 10.642378 | H21: =IFERROR(H20/H18,"") -> 7.8686481 | I21: =IFERROR(I20/I18,"") -> 9.4915308 | J21: =IFERROR(J20/J18,"") -> 6.1186481 | K21: =IFERROR(K20/K18,"") -> 7.1581974 | L21: =IFERROR(L20/L18,"") -> 6.1585609 | M21: =IFERROR(M20/M18,"") -> 6.390273 | N21: =IFERROR(N20/N18,"") -> 5.390273 | ... Y21: =IFERROR(Y20/Y18,"") -> -5.609727
A22: 8697343650027 | B22: FEAST IQF ONION RINGS 12*450 GR | C22: 洋蔥圈 | D22: 72 | E22: FCST / 出貨需求 | G22: 43.388889 | H22: 56.839444 | I22: 39.05 | J22: 56.839444 | K22: 39.05 | L22: 56.839444 | M22: 39.05 | N22: 43.388889 | O22: 43.388889 | P22: 43.388889 | Q22: 43.388889 | R22: 43.388889 | S22: 43.388889 | T22: 43.388889 | U22: 43.388889 | V22: 43.388889 | W22: 43.388889 | X22: 43.388889 | Y22: 43.388889
E23: order / 訂貨板數 | G23: 6 | L23: 7
E24: Stock / 月末庫存 | F24: 12.808889 | G24: =IF(G22="","",$F24-G22+G23*$D22) -> 401.42 | H24: =IF(H22="","",G24-H22+H23*$D22) -> 344.58056 | I24: =IF(I22="","",H24-I22+I23*$D22) -> 305.53056 | J24: =IF(J22="","",I24-J22+J23*$D22) -> 248.69111 | K24: =IF(K22="","",J24-K22+K23*$D22) -> 209.64111 | L24: =IF(L22="","",K24-L22+L23*$D22) -> 656.80167 | M24: =IF(M22="","",L24-M22+M23*$D22) -> 617.75167 | N24: =IF(N22="","",M24-N22+N23*$D22) -> 574.36278 | O24: =IF(O22="","",N24-O22+O23*$D22) -> 530.97389 | ... Y24: =IF(Y22="","",X24-Y22+Y23*$D22) -> 97.085
E25: cover month / 可涵蓋月數 | F25: =IFERROR(F24/G22,"") -> 0.29521127 | G25: =IFERROR(G24/G22,"") -> 9.2516773 | H25: =IFERROR(H24/H22,"") -> 6.0623491 | I25: =IFERROR(I24/I22,"") -> 7.8240859 | J25: =IFERROR(J24/J22,"") -> 4.3753262 | K25: =IFERROR(K24/K22,"") -> 5.3685304 | L25: =IFERROR(L24/L22,"") -> 11.555385 | M25: =IFERROR(M24/M22,"") -> 15.819505 | N25: =IFERROR(N24/N22,"") -> 13.237554 | ... Y25: =IFERROR(Y24/Y22,"") -> 2.2375544
A26: 8697343550129 | B26: FEAST IQF BROCCOLI 12*500 g | C26: 急凍青花菜 | D26: 72 | E26: FCST / 出貨需求 | G26: 13.947368 | H26: 16.039474 | I26: 16.039474 | J26: 16.039474 | K26: 16.039474 | L26: 16.039474 | M26: 16.039474 | N26: 13.947368 | O26: 13.947368 | P26: 13.947368 | Q26: 13.947368 | R26: 13.947368 | S26: 13.947368 | T26: 13.947368 | U26: 13.947368 | V26: 13.947368 | W26: 13.947368 | X26: 13.947368 | Y26: 13.947368
E27: order / 訂貨板數 | G27: 1 | L27: 2
E28: Stock / 月末庫存 | F28: 87.635965 | G28: =IF(G26="","",$F28-G26+G27*$D26) -> 145.6886 | H28: =IF(H26="","",G28-H26+H27*$D26) -> 129.64912 | I28: =IF(I26="","",H28-I26+I27*$D26) -> 113.60965 | J28: =IF(J26="","",I28-J26+J27*$D26) -> 97.570175 | K28: =IF(K26="","",J28-K26+K27*$D26) -> 81.530702 | L28: =IF(L26="","",K28-L26+L27*$D26) -> 209.49123 | M28: =IF(M26="","",L28-M26+M27*$D26) -> 193.45175 | N28: =IF(N26="","",M28-N26+N27*$D26) -> 179.50439 | O28: =IF(O26="","",N28-O26+O27*$D26) -> 165.55702 | ... Y28: =IF(Y26="","",X28-Y26+Y27*$D26) -> 26.083333
E29: cover month / 可涵蓋月數 | F29: =IFERROR(F28/G26,"") -> 6.2833333 | G29: =IFERROR(G28/G26,"") -> 10.445597 | H29: =IFERROR(H28/H26,"") -> 8.0831282 | I29: =IFERROR(I28/I26,"") -> 7.0831282 | J29: =IFERROR(J28/J26,"") -> 6.0831282 | K29: =IFERROR(K28/K26,"") -> 5.0831282 | L29: =IFERROR(L28/L26,"") -> 13.060979 | M29: =IFERROR(M28/M26,"") -> 12.060979 | N29: =IFERROR(N28/N26,"") -> 12.870126 | ... Y29: =IFERROR(Y28/Y26,"") -> 1.8701258
A30: 8697343500200 | B30: FEAST IQF GREEN BEANS 16*450 GR | C30: 急凍四季豆 | D30: 80 | E30: FCST / 出貨需求 | G30: 5.720339 | H30: 5.720339 | I30: 6.4639831 | J30: 5.434322 | K30: 6.4639831 | L30: 5.434322 | M30: 6.4639831 | N30: 5.720339 | O30: 5.720339 | P30: 5.720339 | Q30: 5.720339 | R30: 5.720339 | S30: 5.720339 | T30: 5.720339 | U30: 5.720339 | V30: 5.720339 | W30: 5.720339 | X30: 5.720339 | Y30: 5.720339
E31: order / 訂貨板數 | L31: 1
E32: Stock / 月末庫存 | F32: 55.404661 | G32: =IF(G30="","",$F32-G30+G31*$D30) -> 49.684322 | H32: =IF(H30="","",G32-H30+H31*$D30) -> 43.963983 | I32: =IF(I30="","",H32-I30+I31*$D30) -> 37.5 | J32: =IF(J30="","",I32-J30+J31*$D30) -> 32.065678 | K32: =IF(K30="","",J32-K30+K31*$D30) -> 25.601695 | L32: =IF(L30="","",K32-L30+L31*$D30) -> 100.16737 | M32: =IF(M30="","",L32-M30+M31*$D30) -> 93.70339 | N32: =IF(N30="","",M32-N30+N31*$D30) -> 87.983051 | O32: =IF(O30="","",N32-O30+O31*$D30) -> 82.262712 | ... Y32: =IF(Y30="","",X32-Y30+Y31*$D30) -> 25.059322
E33: cover month / 可涵蓋月數 | F33: =IFERROR(F32/G30,"") -> 9.6855556 | G33: =IFERROR(G32/G30,"") -> 8.6855556 | H33: =IFERROR(H32/H30,"") -> 7.6855556 | I33: =IFERROR(I32/I30,"") -> 5.8013766 | J33: =IFERROR(J32/J30,"") -> 5.9005848 | K33: =IFERROR(K32/K30,"") -> 3.9606686 | L33: =IFERROR(L32/L30,"") -> 18.432359 | M33: =IFERROR(M32/M30,"") -> 14.496231 | N33: =IFERROR(N32/N30,"") -> 15.380741 | ... Y33: =IFERROR(Y32/Y30,"") -> 4.3807407
A34: 8697343550013 | B34: FEAST IQF GREEN PEAS | C34: 急速冷凍豌豆 | D34: 80 | E34: FCST / 出貨需求 | G34: 4.5762712 | H34: 4.5762712 | I34: 5.0338983 | J34: 4.3474576 | K34: 5.0338983 | L34: 4.3474576 | M34: 5.0338983 | N34: 4.5762712 | O34: 4.5762712 | P34: 4.5762712 | Q34: 4.5762712 | R34: 4.5762712 | S34: 4.5762712 | T34: 4.5762712 | U34: 4.5762712 | V34: 4.5762712 | W34: 4.5762712 | X34: 4.5762712 | Y34: 4.5762712
E35: order / 訂貨板數
E36: Stock / 月末庫存 | F36: 60.523729 | G36: =IF(G34="","",$F36-G34+G35*$D34) -> 55.947458 | H36: =IF(H34="","",G36-H34+H35*$D34) -> 51.371186 | I36: =IF(I34="","",H36-I34+I35*$D34) -> 46.337288 | J36: =IF(J34="","",I36-J34+J35*$D34) -> 41.989831 | K36: =IF(K34="","",J36-K34+K35*$D34) -> 36.955932 | L36: =IF(L34="","",K36-L34+L35*$D34) -> 32.608475 | M36: =IF(M34="","",L36-M34+M35*$D34) -> 27.574576 | N36: =IF(N34="","",M36-N34+N35*$D34) -> 22.998305 | O36: =IF(O34="","",N36-O34+O35*$D34) -> 18.422034 | ... Y36: =IF(Y34="","",X36-Y34+Y35*$D34) -> -27.340678
E37: cover month / 可涵蓋月數 | F37: =IFERROR(F36/G34,"") -> 13.225556 | G37: =IFERROR(G36/G34,"") -> 12.225556 | H37: =IFERROR(H36/H34,"") -> 11.225556 | I37: =IFERROR(I36/I34,"") -> 9.2050505 | J37: =IFERROR(J36/J34,"") -> 9.6584795 | K37: =IFERROR(K36/K34,"") -> 7.3414141 | L37: =IFERROR(L36/L34,"") -> 7.5005848 | M37: =IFERROR(M36/M34,"") -> 5.4777778 | N37: =IFERROR(N36/N34,"") -> 5.0255556 | ... Y37: =IFERROR(Y36/Y34,"") -> -5.9744444
B38: FEAST IQF SPINACH 12*450 GR | C38: 急速冷凍菠菜 | D38: 72 | E38: FCST / 出貨需求 | K38: 60 | L38: 60 | M38: 60 | N38: 60 | O38: 60 | P38: 60
E39: order / 訂貨板數
E40: Stock / 月末庫存 | F40: 0 | G40: =IF(G38="","",$F40-G38+G39*$D38) | H40: =IF(H38="","",G40-H38+H39*$D38) | I40: =IF(I38="","",H40-I38+I39*$D38) | J40: =IF(J38="","",I40-J38+J39*$D38) | K40: =IF(K38="","",J40-K38+K39*$D38) -> -60 | L40: =IF(L38="","",K40-L38+L39*$D38) -> -120 | M40: =IF(M38="","",L40-M38+M39*$D38) -> -180 | N40: =IF(N38="","",M40-N38+N39*$D38) -> -240 | O40: =IF(O38="","",N40-O38+O39*$D38) -> -300 | ... Y40: =IF(Y38="","",X40-Y38+Y39*$D38)
E41: cover month / 可涵蓋月數 | F41: =IFERROR(F40/G38,"") | G41: =IFERROR(G40/G38,"") | H41: =IFERROR(H40/H38,"") | I41: =IFERROR(I40/I38,"") | J41: =IFERROR(J40/J38,"") | K41: =IFERROR(K40/K38,"") -> -1 | L41: =IFERROR(L40/L38,"") -> -2 | M41: =IFERROR(M40/M38,"") -> -3 | N41: =IFERROR(N40/N38,"") -> -4 | ... Y41: =IFERROR(Y40/Y38,"")
